Workbook

Sheet Rozpis podle pokojů
A1: 🏠 TÝDENNÍ ROZPIS ÚKLIDOVÝCH SLUŽEB NA BYTĚ
A2: 4 pokoje • 4 společné služby (Schody, Kuchyň, Odpadky, Předsíň) • Koupelna & WC po dvojicích (P1+P2 a P3+P4)
A4: Datum začátku: | B4: 46300 | C4: ← Zadáním nového data pondělí se automaticky přepočítá celý rok (všechny dny v tabulce)
A6: Týden | B6: Od (Po) | C6: Do (Ne) | D6: Pokoj 1 (Společné + Koup/WC) | E6: Pokoj 2 (Společné + Koup/WC) | F6: Pokoj 3 (Společné + Koup/WC) | G6: Pokoj 4 (Společné + Koup/WC)
A7: Týden 1 | B7: =$B$4 + (0*7) | C7: =B7 + 6 | D7: Schody + Koupelna | E7: Kuchyň + WC | F7: Odpadky + Koupelna | G7: Předsíň + WC
A8: Týden 2 | B8: =$B$4 + (1*7) | C8: =B8 + 6 | D8: Předsíň + WC | E8: Schody + Koupelna | F8: Kuchyň + WC | G8: Odpadky + Koupelna
A9: Týden 3 | B9: =$B$4 + (2*7) | C9: =B9 + 6 | D9: Odpadky + Koupelna | E9: Předsíň + WC | F9: Schody + Koupelna | G9: Kuchyň + WC
A10: Týden 4 | B10: =$B$4 + (3*7) | C10: =B10 + 6 | D10: Kuchyň + WC | E10: Odpadky + Koupelna | F10: Předsíň + WC | G10: Schody + Koupelna
A11: Týden 5 | B11: =$B$4 + (4*7) | C11: =B11 + 6 | D11: Schody + Koupelna | E11: Kuchyň + WC | F11: Odpadky + Koupelna | G11: Předsíň + WC
A12: Týden 6 | B12: =$B$4 + (5*7) | C12: =B12 + 6 | D12: Předsíň + WC | E12: Schody + Koupelna | F12: Kuchyň + WC | G12: Odpadky + Koupelna
A13: Týden 7 | B13: =$B$4 + (6*7) | C13: =B13 + 6 | D13: Odpadky + Koupelna | E13: Předsíň + WC | F13: Schody + Koupelna | G13: Kuchyň + WC
A14: Týden 8 | B14: =$B$4 + (7*7) | C14: =B14 + 6 | D14: Kuchyň + WC | E14: Odpadky + Koupelna | F14: Předsíň + WC | G14: Schody + Koupelna
A15: Týden 9 | B15: =$B$4 + (8*7) | C15: =B15 + 6 | D15: Schody + Koupelna | E15: Kuchyň + WC | F15: Odpadky + Koupelna | G15: Předsíň + WC
A16: Týden 10 | B16: =$B$4 + (9*7) | C16: =B16 + 6 | D16: Předsíň + WC | E16: Schody + Koupelna | F16: Kuchyň + WC | G16: Odpadky + Koupelna
A17: Týden 11 | B17: =$B$4 + (10*7) | C17: =B17 + 6 | D17: Odpadky + Koupelna | E17: Předsíň + WC | F17: Schody + Koupelna | G17: Kuchyň + WC
A18: Týden 12 | B18: =$B$4 + (11*7) | C18: =B18 + 6 | D18: Kuchyň + WC | E18: Odpadky + Koupelna | F18: Předsíň + WC | G18: Schody + Koupelna
A19: Týden 13 | B19: =$B$4 + (12*7) | C19: =B19 + 6 | D19: Schody + Koupelna | E19: Kuchyň + WC | F19: Odpadky + Koupelna | G19: Předsíň + WC
A20: Týden 14 | B20: =$B$4 + (13*7) | C20: =B20 + 6 | D20: Předsíň + WC | E20: Schody + Koupelna | F20: Kuchyň + WC | G20: Odpadky + Koupelna
A21: Týden 15 | B21: =$B$4 + (14*7) | C21: =B21 + 6 | D21: Odpadky + Koupelna | E21: Předsíň + WC | F21: Schody + Koupelna | G21: Kuchyň + WC
A22: Týden 16 | B22: =$B$4 + (15*7) | C22: =B22 + 6 | D22: Kuchyň + WC | E22: Odpadky + Koupelna | F22: Předsíň + WC | G22: Schody + Koupelna
A23: Týden 17 | B23: =$B$4 + (16*7) | C23: =B23 + 6 | D23: Schody + Koupelna | E23: Kuchyň + WC | F23: Odpadky + Koupelna | G23: Předsíň + WC
A24: Týden 18 | B24: =$B$4 + (17*7) | C24: =B24 + 6 | D24: Předsíň + WC | E24: Schody + Koupelna | F24: Kuchyň + WC | G24: Odpadky + Koupelna
A25: Týden 19 | B25: =$B$4 + (18*7) | C25: =B25 + 6 | D25: Odpadky + Koupelna | E25: Předsíň + WC | F25: Schody + Koupelna | G25: Kuchyň + WC
A26: Týden 20 | B26: =$B$4 + (19*7) | C26: =B26 + 6 | D26: Kuchyň + WC | E26: Odpadky + Koupelna | F26: Předsíň + WC | G26: Schody + Koupelna
A27: Týden 21 | B27: =$B$4 + (20*7) | C27: =B27 + 6 | D27: Schody + Koupelna | E27: Kuchyň + WC | F27: Odpadky + Koupelna | G27: Předsíň + WC
A28: Týden 22 | B28: =$B$4 + (21*7) | C28: =B28 + 6 | D28: Předsíň + WC | E28: Schody + Koupelna | F28: Kuchyň + WC | G28: Odpadky + Koupelna
A29: Týden 23 | B29: =$B$4 + (22*7) | C29: =B29 + 6 | D29: Odpadky + Koupelna | E29: Předsíň + WC | F29: Schody + Koupelna | G29: Kuchyň + WC
A30: Týden 24 | B30: =$B$4 + (23*7) | C30: =B30 + 6 | D30: Kuchyň + WC | E30: Odpadky + Koupelna | F30: Předsíň + WC | G30: Schody + Koupelna
A31: Týden 25 | B31: =$B$4 + (24*7) | C31: =B31 + 6 | D31: Schody + Koupelna | E31: Kuchyň + WC | F31: Odpadky + Koupelna | G31: Předsíň + WC
A32: Týden 26 | B32: =$B$4 + (25*7) | C32: =B32 + 6 | D32: Předsíň + WC | E32: Schody + Koupelna | F32: Kuchyň + WC | G32: Odpadky + Koupelna
A33: Týden 27 | B33: =$B$4 + (26*7) | C33: =B33 + 6 | D33: Odpadky + Koupelna | E33: Předsíň + WC | F33: Schody + Koupelna | G33: Kuchyň + WC
A34: Týden 28 | B34: =$B$4 + (27*7) | C34: =B34 + 6 | D34: Kuchyň + WC | E34: Odpadky + Koupelna | F34: Předsíň + WC | G34: Schody + Koupelna
A35: Týden 29 | B35: =$B$4 + (28*7) | C35: =B35 + 6 | D35: Schody + Koupelna | E35: Kuchyň + WC | F35: Odpadky + Koupelna | G35: Předsíň + WC
A36: Týden 30 | B36: =$B$4 + (29*7) | C36: =B36 + 6 | D36: Předsíň + WC | E36: Schody + Koupelna | F36: Kuchyň + WC | G36: Odpadky + Koupelna
A37: Týden 31 | B37: =$B$4 + (30*7) | C37: =B37 + 6 | D37: Odpadky + Koupelna | E37: Předsíň + WC | F37: Schody + Koupelna | G37: Kuchyň + WC
A38: Týden 32 | B38: =$B$4 + (31*7) | C38: =B38 + 6 | D38: Kuchyň + WC | E38: Odpadky + Koupelna | F38: Předsíň + WC | G38: Schody + Koupelna
A39: Týden 33 | B39: =$B$4 + (32*7) | C39: =B39 + 6 | D39: Schody + Koupelna | E39: Kuchyň + WC | F39: Odpadky + Koupelna | G39: Předsíň + WC
A40: Týden 34 | B40: =$B$4 + (33*7) | C40: =B40 + 6 | D40: Předsíň + WC | E40: Schody + Koupelna | F40: Kuchyň + WC | G40: Odpadky + Koupelna
A41: Týden 35 | B41: =$B$4 + (34*7) | C41: =B41 + 6 | D41: Odpadky + Koupelna | E41: Předsíň + WC | F41: Schody + Koupelna | G41: Kuchyň + WC
A42: Týden 36 | B42: =$B$4 + (35*7) | C42: =B42 + 6 | D42: Kuchyň + WC | E42: Odpadky + Koupelna | F42: Předsíň + WC | G42: Schody + Koupelna
...

Sheet Rozpis podle služeb
A1: 📋 ROZPIS PODLE OBLASTÍ A SLUŽEB
A2: Přehled kdo má v daném týdnu konkrétní oblast (barevně zvýrazněno podle pokoje)
A4: TERMÍN | D4: 🧹 SPOLEČNÉ PROSTORY (ROTACE VŠECH 4 POKOJŮ) | H4: 🚿 KOUPELNY A ZÁCHODY (ROTACE DVOJIC)
A5: Týden | B5: Od (Po) | C5: Do (Ne) | D5: Schody | E5: Kuchyň | F5: Odpadky | G5: Předsíň | H5: Koupelna (P1-P2) | I5: WC (P1-P2) | J5: Koupelna (P3-P4) | K5: WC (P3-P4)
A6: Týden 1 | B6: ='Rozpis podle pokojů'!B7 | C6: ='Rozpis podle pokojů'!C7 | D6: Pokoj 1 | E6: Pokoj 2 | F6: Pokoj 3 | G6: Pokoj 4 | H6: Pokoj 1 | I6: Pokoj 2 | J6: Pokoj 3 | K6: Pokoj 4
A7: Týden 2 | B7: ='Rozpis podle pokojů'!B8 | C7: ='Rozpis podle pokojů'!C8 | D7: Pokoj 2 | E7: Pokoj 3 | F7: Pokoj 4 | G7: Pokoj 1 | H7: Pokoj 2 | I7: Pokoj 1 | J7: Pokoj 4 | K7: Pokoj 3
A8: Týden 3 | B8: ='Rozpis podle pokojů'!B9 | C8: ='Rozpis podle pokojů'!C9 | D8: Pokoj 3 | E8: Pokoj 4 | F8: Pokoj 1 | G8: Pokoj 2 | H8: Pokoj 1 | I8: Pokoj 2 | J8: Pokoj 3 | K8: Pokoj 4
A9: Týden 4 | B9: ='Rozpis podle pokojů'!B10 | C9: ='Rozpis podle pokojů'!C10 | D9: Pokoj 4 | E9: Pokoj 1 | F9: Pokoj 2 | G9: Pokoj 3 | H9: Pokoj 2 | I9: Pokoj 1 | J9: Pokoj 4 | K9: Pokoj 3
A10: Týden 5 | B10: ='Rozpis podle pokojů'!B11 | C10: ='Rozpis podle pokojů'!C11 | D10: Pokoj 1 | E10: Pokoj 2 | F10: Pokoj 3 | G10: Pokoj 4 | H10: Pokoj 1 | I10: Pokoj 2 | J10: Pokoj 3 | K10: Pokoj 4
A11: Týden 6 | B11: ='Rozpis podle pokojů'!B12 | C11: ='Rozpis podle pokojů'!C12 | D11: Pokoj 2 | E11: Pokoj 3 | F11: Pokoj 4 | G11: Pokoj 1 | H11: Pokoj 2 | I11: Pokoj 1 | J11: Pokoj 4 | K11: Pokoj 3
A12: Týden 7 | B12: ='Rozpis podle pokojů'!B13 | C12: ='Rozpis podle pokojů'!C13 | D12: Pokoj 3 | E12: Pokoj 4 | F12: Pokoj 1 | G12: Pokoj 2 | H12: Pokoj 1 | I12: Pokoj 2 | J12: Pokoj 3 | K12: Pokoj 4
A13: Týden 8 | B13: ='Rozpis podle pokojů'!B14 | C13: ='Rozpis podle pokojů'!C14 | D13: Pokoj 4 | E13: Pokoj 1 | F13: Pokoj 2 | G13: Pokoj 3 | H13: Pokoj 2 | I13: Pokoj 1 | J13: Pokoj 4 | K13: Pokoj 3
A14: Týden 9 | B14: ='Rozpis podle pokojů'!B15 | C14: ='Rozpis podle pokojů'!C15 | D14: Pokoj 1 | E14: Pokoj 2 | F14: Pokoj 3 | G14: Pokoj 4 | H14: Pokoj 1 | I14: Pokoj 2 | J14: Pokoj 3 | K14: Pokoj 4
A15: Týden 10 | B15: ='Rozpis podle pokojů'!B16 | C15: ='Rozpis podle pokojů'!C16 | D15: Pokoj 2 | E15: Pokoj 3 | F15: Pokoj 4 | G15: Pokoj 1 | H15: Pokoj 2 | I15: Pokoj 1 | J15: Pokoj 4 | K15: Pokoj 3
A16: Týden 11 | B16: ='Rozpis podle pokojů'!B17 | C16: ='Rozpis podle pokojů'!C17 | D16: Pokoj 3 | E16: Pokoj 4 | F16: Pokoj 1 | G16: Pokoj 2 | H16: Pokoj 1 | I16: Pokoj 2 | J16: Pokoj 3 | K16: Pokoj 4
A17: Týden 12 | B17: ='Rozpis podle pokojů'!B18 | C17: ='Rozpis podle pokojů'!C18 | D17: Pokoj 4 | E17: Pokoj 1 | F17: Pokoj 2 | G17: Pokoj 3 | H17: Pokoj 2 | I17: Pokoj 1 | J17: Pokoj 4 | K17: Pokoj 3
... A57: Týden 52 | B57: ='Rozpis podle pokojů'!B58 | C57: ='Rozpis podle pokojů'!C58 | D57: Pokoj 4 | E57: Pokoj 1 | F57: Pokoj 2 | G57: Pokoj 3 | H57: Pokoj 2 | I57: Pokoj 1 | J57: Pokoj 4 | K57: Pokoj 3

Sheet Náplň služeb a pravidla
A1: 📖 NÁPLŇ ÚKLIDOVÝCH SLUŽEB A PRAVIDLA BYTU
A2: Přesný rozpis činností pro každou službu, aby každý věděl, co má udělat a předešlo se dohadům.
A4: 🧹 SCHODY — (Společné prostory domu)
A5: • | B5: Zamést a vytřít celé naše patro (prostor chodby přímo před bytem).
A6: • | B6: Zamést a vytřít dvoje schody směrem dolů včetně mezipatra.
A7: • | B7: Zkontrolovat, že na mezipatře / schodech nezůstaly žádné odpadky, letáky nebo kamínky.
A8: • | B8: Doporučený čas splnění: pátek odpoledne nebo sobota dopoledne.
A11: 🍳 KUCHYŇ — (Společná zóna vaření)
A12: • | B12: Starat se o kuchyňskou linku, dřez a varnou desku (otírat mastnotu a drobky).
A13: • | B13: Průběžně vyndávat umytou myčku a uklízet nádobí do skříněk.
A14: • | B14: Zapnout myčku, jakmile se naplní (nenechávat špinavé nádobí hromadit ve dřezu).
A15: • | B15: Pravidelně zametat a vytírat podlahu v kuchyni (dle potřeby i v týdnu, min. 1× důkladně na závěr).
A18: 🗑️ ODPADKY — (Čistý a voňavý byt)
A19: • | B19: Pravidelně vynášet pytle se směsným odpadem, jakmile jsou plné (nečekat na přetečení).
A20: • | B20: Po vynesení koše VŽDY ihned nasadit nový čistý pytel!
A21: • | B21: Vynášet tříděný odpad (plast, papír, plechovky, sklo) do příslušných kontejnerů.
A22: • | B22: Udržovat prostor kolem odpadkových košů čistý (žádné skvrny ani kapky na podlaze).
A25: 🛋️ PŘEDSÍŇ — (Vstupní společný prostor)
A26: • | B26: Zametat a vytírat podlahu v předsíni (zejména rohožku, vstup a prostor botníku).
A27: • | B27: Urovnat boty v botníku a věšáky u vchodu.
A28: • | B28: Stlát gauč / postel v předsíni, složit deky a polštáře, udržovat estetický pořádek.
A29: • | B29: Otřít prach na botníku a povrchu skříněk.
A32: 🚿 KOUPELNA (Privátní: P1+P2 nebo P3+P4) — (Pokoje 1 & 2 mají svou • Pokoje 3 & 4 mají svou)
A33: • | B33: Vyčistit umyvadlo, baterii a zrcadlo (odstranit zaschlou vodu a zubní pastu).
A34: • | B34: Důkladně vymýt sprchový kout / vanu a odstranit vlasy ze sítka/odpadu.
A35: • | B35: Vytřít podlahu v koupelně.
A36: • | B36: Zkontrolovat předložku a vyvětrat vlhkost.
A39: 🚽 ZÁCHOD (Privátní: P1+P2 nebo P3+P4) — (Pokoje 1 & 2 mají své • Pokoje 3 & 4 mají své)
A40: • | B40: Důkladně vyčistit mísu WC čističem a štětkou.
A41: • | B41: Dezinfekčním sprejem/hadříkem otřít prkénko (shora i zespodu), splachovadlo a okolí.
A42: • | B42: Zkontrolovat stav toaletního papíru a včas doplnit náhradní ruličky.
A43: • | B43: Vytřít podlahu na záchodě.
A46: ⚖️ ZLATÁ PRAVIDLA SPOLUBYDLENÍ
A47: ★ | B47: Předání služeb: | C47: Služba se oficiálně předává v NEDĚLI do 20:00 (do té doby je vše hotovo).
A48: ★ | B48: Nepřítomnost: | C48: Když někdo odjíždí na týden pryč, je jeho povinností si zajistit výměnu s jiným pokojem.
A49: ★ | B49: Průběžný pořádek: | C49: Služba neuklízí cizí nepořádek! Každý po sobě ihned utře linku, když něco rozlije, a udržuje pořádek.
A50: ★ | B50: Žádné nádobí ve dřezu: | C50: Ve dřezu nesmí zůstávat nádobí – plný dřez se nedá používat. Při plné myčce odložit vedle na linku a pak do myčky, nebo hned umýt.
A51: ★ | B51: Spotřební materiál a chemie: | C51: Když dochází jar, tablety do myčky, WC gel, toaletní papír nebo pytle do koše, tak to koupíš a hodíš do SettleUp.
